<?xml version="1.0" ?>
<!-- =================================================================================== -->
<!-- |    This document was autogenerated by xacro from robot.urdf.xacro               | -->
<!-- |    EDITING THIS FILE BY HAND IS NOT RECOMMENDED                                 | -->
<!-- =================================================================================== -->
<robot name="my_robot">
  <material name="grey">
    <color rgba="0.7 0.7 0.7 1"/>
  </material>
  <material name="green">
    <color rgba="0 0.6 0 1"/>
  </material>
  <material name="white">
    <color rgba="1 1 1 1"/>
  </material>
  <material name="black">
    <color rgba="0 0 0 1"/>
  </material>
  <material name="orange">
    <color rgba="1 0.3 0.1 1"/>
  </material>
  <material name="invisible">
    <color rgba="0.0 0.0 0.0 0.0"/>
  </material>
  <!-- <xacro:property name="wheeltrack" value="" -->
  <link name="base_link">
    <collision>
      <origin rpy="0 0 0" xyz="0 0 0"/>
      <geometry>
        <box size="0.25 0.17 0.06"/>
      </geometry>
    </collision>
    <visual>
      <origin rpy="0 0 0" xyz="0 0 0"/>
      <geometry>
        <box size="0.25 0.17 0.06"/>
      </geometry>
      <material name="orange"/>
    </visual>
    <inertial>
      <origin rpy="0 0 0" xyz="0 0 0"/>
      <mass value="1"/>
      <inertia ixx="0.000270" ixy="0.0" ixz="0.0" iyy="0.000270" iyz="0.0" izz="0.000426"/>
    </inertial>
  </link>
  <!-- rear wheels -->
  <!-- virtual rear wheel -->
  <link name="virtual_rear_wheel">
    <visual>
      <origin rpy="1.5707963267948966 0 1.5707963267948966" xyz="0 0 0"/>
      <geometry>
        <cylinder length="0.01" radius="0.0215"/>
      </geometry>
      <material name="invisible"/>
    </visual>
  </link>
  <joint name="virtual_rear_wheel_joint" type="continuous">
    <parent link="base_link"/>
    <child link="virtual_rear_wheel"/>
    <origin rpy="0 0 1.5707963267948966" xyz="-0.08 0 -0.03"/>
    <axis rpy="0 0 0" xyz="1 0 0"/>
    <limit effort="100.0" velocity="100.0"/>
    <dynamics damping="0.2"/>
  </joint>
  <!-- rear right wheel -->
  <link name="rear_right_wheel">
    <collision>
      <origin rpy="1.5707963267948966 0 1.5707963267948966" xyz="0 0 0"/>
      <geometry>
        <cylinder length="0.018" radius="0.0215"/>
      </geometry>
    </collision>
    <visual>
      <origin rpy="1.5707963267948966 0 1.5707963267948966" xyz="0 0 0"/>
      <geometry>
        <cylinder length="0.018" radius="0.0215"/>
      </geometry>
      <material name="black"/>
    </visual>
    <inertial>
      <origin rpy="1.5707963267948966 0 1.5707963267948966" xyz="0 0 0"/>
      <mass value="0.1"/>
      <inertia ixx="0.000270" ixy="0.0" ixz="0.0" iyy="0.000270" iyz="0.0" izz="0.000426"/>
    </inertial>
  </link>
  <joint name="rear_right_wheel_joint" type="continuous">
    <parent link="base_link"/>
    <child link="rear_right_wheel"/>
    <origin rpy="0 0 1.5707963267948966" xyz="-0.08 0.085 -0.03"/>
    <axis rpy="0 0 0" xyz="1 0 0"/>
    <limit effort="100.0" velocity="100.0"/>
    <dynamics damping="0.2"/>
    <mimic joint="virtual_rear_wheel_joint" multiplier="1.0" offset="0.0"/>
  </joint>
  <!-- rear left wheel -->
  <link name="rear_left_wheel">
    <collision>
      <origin rpy="1.5707963267948966 0 1.5707963267948966" xyz="0 0 0"/>
      <geometry>
        <cylinder length="0.018" radius="0.0215"/>
      </geometry>
    </collision>
    <visual>
      <origin rpy="1.5707963267948966 0 1.5707963267948966" xyz="0 0 0"/>
      <geometry>
        <cylinder length="0.018" radius="0.0215"/>
      </geometry>
      <material name="black"/>
    </visual>
    <inertial>
      <origin rpy="1.5707963267948966 0 1.5707963267948966" xyz="0 0 0"/>
      <mass value="0.1"/>
      <inertia ixx="0.000270" ixy="0.0" ixz="0.0" iyy="0.000270" iyz="0.0" izz="0.000426"/>
    </inertial>
  </link>
  <joint name="rear_left_wheel_joint" type="continuous">
    <parent link="base_link"/>
    <child link="rear_left_wheel"/>
    <origin rpy="0 0 1.5707963267948966" xyz="-0.08 -0.085 -0.03"/>
    <axis rpy="0 0 0" xyz="1 0 0"/>
    <limit effort="100.0" velocity="100.0"/>
    <dynamics damping="0.2"/>
    <mimic joint="virtual_rear_wheel_joint" multiplier="1.0" offset="0.0"/>
  </joint>
  <!-- front wheels -->
  <!-- virtual front wheel -->
  <link name="virtual_front_wheel">
    <visual>
      <origin rpy="1.5707963267948966 0 1.5707963267948966" xyz="0 0 0"/>
      <geometry>
        <cylinder length="0.01" radius="0.0215"/>
      </geometry>
      <material name="invisible"/>
    </visual>
  </link>
  <joint name="virtual_front_wheel_joint" type="revolute">
    <parent link="base_link"/>
    <child link="virtual_front_wheel"/>
    <origin rpy="0 0 1.5707963267948966" xyz="0.08 0 -0.03"/>
    <axis xyz="0 0 1"/>
    <limit effort="100.0" lower="-0.7853" upper="0.7853" velocity="100.0"/>
    <dynamics damping="0.2"/>
  </joint>
  <!-- front right wheel -->
  <link name="front_right_wheel">
    <collision>
      <origin rpy="1.5707963267948966 0 1.5707963267948966" xyz="0 0 0"/>
      <geometry>
        <cylinder length="0.018" radius="0.0215"/>
      </geometry>
    </collision>
    <visual>
      <origin rpy="1.5707963267948966 0 1.5707963267948966" xyz="0 0 0"/>
      <geometry>
        <cylinder length="0.018" radius="0.0215"/>
      </geometry>
      <material name="black"/>
    </visual>
    <inertial>
      <origin rpy="1.5707963267948966 0 1.5707963267948966" xyz="0 0 0"/>
      <mass value="0.1"/>
      <inertia ixx="0.000270" ixy="0.0" ixz="0.0" iyy="0.000270" iyz="0.0" izz="0.000426"/>
    </inertial>
  </link>
  <joint name="front_right_wheel_joint" type="revolute">
    <parent link="base_link"/>
    <child link="front_right_wheel"/>
    <origin rpy="0 0 1.5707963267948966" xyz="0.08 0.085 -0.03"/>
    <axis xyz="0 0 1"/>
    <limit effort="100.0" lower="-0.7853" upper="0.7853" velocity="100.0"/>
    <dynamics damping="0.2"/>
    <mimic joint="virtual_front_wheel_joint" multiplier="1.0" offset="0.0"/>
  </joint>
  <link name="front_left_wheel">
    <collision>
      <origin rpy="1.5707963267948966 0 1.5707963267948966" xyz="0 0 0"/>
      <geometry>
        <cylinder length="0.018" radius="0.0215"/>
      </geometry>
    </collision>
    <visual>
      <origin rpy="1.5707963267948966 0 1.5707963267948966" xyz="0 0 0"/>
      <geometry>
        <cylinder length="0.018" radius="0.0215"/>
      </geometry>
      <material name="black"/>
    </visual>
    <inertial>
      <origin rpy="1.5707963267948966 0 1.5707963267948966" xyz="0 0 0"/>
      <mass value="0.1"/>
      <inertia ixx="0.000270" ixy="0.0" ixz="0.0" iyy="0.000270" iyz="0.0" izz="0.000426"/>
    </inertial>
  </link>
  <joint name="front_left_wheel_joint" type="revolute">
    <parent link="base_link"/>
    <child link="front_left_wheel"/>
    <origin rpy="0 0 1.5707963267948966" xyz="0.08 -0.085 -0.03"/>
    <axis xyz="0 0 1"/>
    <limit effort="100.0" lower="-0.7853" upper="0.7853" velocity="100.0"/>
    <dynamics damping="0.2"/>
    <mimic joint="virtual_front_wheel_joint" multiplier="1.0" offset="0.0"/>
  </joint>
  <ros2_control name="RobotControl" type="system">
    <hardware>
      <plugin>bicdrive_arduino/CarlikeBotSystemHardware</plugin>
      <param name="front_wheel_name">virtual_front_wheel_joint</param>
      <param name="rear_wheel_name">virtual_rear_wheel_joint</param>
      <param name="loop_rate">30</param>
      <!-- <param name="device">/dev/serial/by-path/platform-3610000.usb-usb-0:2.1:1.0-port0</param> -->
      <param name="device">/dev/serial/by-path/pci-0000:00:14.0-usb-0:4:1.0-port0</param>
      <param name="baud_rate">9600</param>
      <param name="timeout_ms">1000</param>
    </hardware>
    <joint name="virtual_front_wheel_joint">
      <command_interface name="position"/>
      <state_interface name="position"/>
    </joint>
    <joint name="virtual_rear_wheel_joint">
      <command_interface name="velocity"/>
      <state_interface name="velocity"/>
    </joint>
  </ros2_control>
  <joint name="laser_joint" type="fixed">
    <parent link="base_link"/>
    <child link="laser_frame"/>
    <origin rpy="0 0 0" xyz="0 0 0.038"/>
  </joint>
  <link name="laser_frame">
    <collision>
      <geometry>
        <cylinder length="0.02" radius="0.04"/>
      </geometry>
    </collision>
    <visual>
      <geometry>
        <cylinder length="0.02" radius="0.04"/>
      </geometry>
      <material name="green"/>
    </visual>
    <inertial>
      <origin rpy="0 0 0" xyz="0 0 0"/>
      <mass value="1.0"/>
      <inertia ixx="0.0004333333333333333" ixy="0.0" ixz="0.0" iyy="0.0004333333333333333" iyz="0.0" izz="0.0008"/>
    </inertial>
  </link>
  <gazebo reference="laser_frame">
    <material>Gazebo/Green</material>
    <sensor name="laser" type="ray">
      <pose>0 0 0 0 0 0</pose>
      <visualize>false</visualize>
      <update_rate>10</update_rate>
      <ray>
        <scan>
          <horizontal>
            <samples>360</samples>
            <resolution>1</resolution>
            <min_angle>-3.14</min_angle>
            <max_angle>3.14</max_angle>
          </horizontal>
        </scan>
        <range>
          <min>1</min>
          <max>60</max>
          <resolution>0.01</resolution>
        </range>
      </ray>
      <plugin filename="libgazebo_ros_ray_sensor.so" name="laser_controller">
        <ros>
          <argument>~/out:=scan</argument>
        </ros>
        <output_type>sensor_msgs/LaserScan</output_type>
        <frame_name>laser_frame</frame_name>
      </plugin>
    </sensor>
  </gazebo>
  <joint name="camera_joint" type="fixed">
    <parent link="base_link"/>
    <child link="camera_link"/>
    <origin rpy="0 0 0" xyz="0.128 0 0"/>
  </joint>
  <link name="camera_link">
    <visual>
      <geometry>
        <box size="0.006 0.02 0.02"/>
      </geometry>
      <material name="green"/>
    </visual>
  </link>
  <joint name="camera_optical_joint" type="fixed">
    <parent link="camera_link"/>
    <child link="camera_link_optical"/>
    <origin rpy="-1.5707963267948966 0 -1.5707963267948966" xyz="0 0 0"/>
  </joint>
  <link name="camera_link_optical"/>
  <gazebo reference="camera_link">
    <material>Gazebo/Green</material>
    <!-- <gravity>true</gravity> -->
    <sensor name="camera" type="depth">
      <pose>0 0 0 0 0 0</pose>
      <visualize>false</visualize>
      <update_rate>10</update_rate>
      <camera>
        <horizontal_fov>1.204</horizontal_fov>
        <image>
          <width>640</width>
          <height>480</height>
          <format>B8G8R8</format>
        </image>
        <clip>
          <near>3</near>
          <far>30.0</far>
        </clip>
      </camera>
      <plugin filename="libgazebo_ros_camera.so" name="camera_controller">
        <frame_name>camera_link_optical</frame_name>
        <min_depth>0.1</min_depth>
        <max_depth>100</max_depth>
      </plugin>
    </sensor>
    <!-- <sensor name="imu_sensor" type="imu">
            <always_on>true</always_on>
            <update_rate>100</update_rate>
            <visualize>true</visualize>
            <topic>__default_topic__</topic>
            <plugin filename="libgazebo_ros_imu_sensor.so" name="imu_plugin">
                <topicName>imu</topicName>
                <bodyName>camera_link</bodyName>
                <updateRateHZ>10.0</updateRateHZ>
                <gaussianNoise>0.0</gaussianNoise>
                <xyzOffset>1 0 0.1</xyzOffset>
                <rpyOffset>0 0 0</rpyOffset>
                <frameName>camera_link</frameName>
            </plugin>
            <pose>0 0 0 0 0 0</pose>
        </sensor> -->
    <!-- <sensor name="imu_sensor" type="imu">
            <plugin filename="libgazebo_ros_imu_sensor.so" name="imu_plugin">
                <ros>
                    <remapping>~/out:=imu</remapping>
                </ros>
                <initial_orientation_as_reference>false</initial_orientation_as_reference>
                </plugin>
                <always_on>true</always_on>
                <update_rate>100</update_rate>
                <visualize>true</visualize>
                <imu>
                <angular_velocity>
                    <x>
                    <noise type="gaussian">
                        <mean>0.0</mean>
                        <stddev>2e-4</stddev>
                        <bias_mean>0.0000075</bias_mean>
                        <bias_stddev>0.0000008</bias_stddev>
                    </noise>
                    </x>
                    <y>
                    <noise type="gaussian">
                        <mean>0.0</mean>
                        <stddev>2e-4</stddev>
                        <bias_mean>0.0000075</bias_mean>
                        <bias_stddev>0.0000008</bias_stddev>
                    </noise>
                    </y>
                    <z>
                    <noise type="gaussian">
                        <mean>0.0</mean>
                        <stddev>2e-4</stddev>
                        <bias_mean>0.0000075</bias_mean>
                        <bias_stddev>0.0000008</bias_stddev>
                    </noise>
                    </z>
                </angular_velocity>
                <linear_acceleration>
                    <x>
                    <noise type="gaussian">
                        <mean>0.0</mean>
                        <stddev>1.7e-2</stddev>
                        <bias_mean>0.1</bias_mean>
                        <bias_stddev>0.001</bias_stddev>
                    </noise>
                    </x>
                    <y>
                    <noise type="gaussian">
                        <mean>0.0</mean>
                        <stddev>1.7e-2</stddev>
                        <bias_mean>0.1</bias_mean>
                        <bias_stddev>0.001</bias_stddev>
                    </noise>
                    </y>
                    <z>
                    <noise type="gaussian">
                        <mean>0.0</mean>
                        <stddev>1.7e-2</stddev>
                        <bias_mean>0.1</bias_mean>
                        <bias_stddev>0.001</bias_stddev>
                    </noise>
                    </z>
                </linear_acceleration>
            </imu>
        </sensor> -->
  </gazebo>
</robot>
