<?xml version="1.0"?>

<robot name="my_robot" xmlns:xacro="http://www.ros.org/wiki/xacro">
    <material name="grey">
        <color rgba="0.7 0.7 0.7 1"/>
    </material>

    <material name="green">
        <color rgba="0 0.6 0 1"/>
    </material>

    <material name="white">
        <color rgba="1 1 1 1"/>
    </material>

    <link name="base_footprint" />

    <joint name="base_joint" type="fixed">
        <parent link="base_footprint" />
        <child link="base_link" />
        <origin xyz="0 0 0.5" rpy="0 0 0" />
    </joint>

    
    <link name='base_link'>
        <inertial> 
          <mass value="1.14"/> 
          <origin xyz="0 0 0.05" rpy="0 0 0"/> 
          <inertia ixx="0.13" ixy="0" ixz="0" iyy="0.4" iyz="0" izz="0.48"/> 
        </inertial> 

        <visual> 
          <origin xyz="0 0 0.05" rpy="0 0 0"/> 
          <geometry> 
            <box size="2 1 0.7"/> 
          </geometry> 
          <material name="green" />
          <material>
            <ambient>0.5 0.5 1.0 1</ambient>
            <diffuse>0.5 0.5 1.0 1</diffuse>
            <specular>0.0 0.0 1.0 1</specular>
          </material>
        </visual>

        <collision> 
          <origin xyz="0 0 0.05" rpy="0 0 0"/> 
          <geometry> 
                <box size="2 1 0.7"/> 
          </geometry> 
        </collision> 
    </link>

    <link name="right_wheel_rear"> 
      <collision> 
        <origin xyz="0 0 0" rpy="0 1.5708 1.5708" />
        <geometry> 
        <cylinder length="0.1" radius="0.2"/> 
        </geometry> 
      </collision> 

      <visual> 
        <origin xyz="0 0 0" rpy="0 1.5708 1.5708" /> 
        <geometry> 
        <cylinder length="0.1" radius="0.2"/> 
        </geometry> 
        <material name="white"/> 
      </visual> 		

      <inertial> 
        <origin xyz="0 0 0" rpy="0 1.5708 1.5708" /> 
        <mass value="0.2"/> 
        <inertia ixx="0.15" ixy="0" ixz="0" iyy="0.15" iyz="0" izz="0.125"/> 
      </inertial> 
    </link>

    <joint name="base_right_wheel_rear_joint" type="continuous"> 
      <parent link="base_link"/> 
      <child link="right_wheel_rear"/> 
      <origin xyz="-0.7 0.52 -0.31" rpy="0 0 0" />  
      <axis xyz="0 1 0" rpy="0 0 0" /> 
      <limit effort="0" velocity="0"/> 
      <dynamics damping="0.0" friction="0.0"/> 
    </joint>

    <link name="left_wheel_rear">
      <collision>
        <origin xyz="0 0 0" rpy="0 1.5708 1.5708" />
        <geometry>
          <cylinder length="0.1" radius="0.2"/>
        </geometry>
      </collision>

      <visual>
        <origin xyz="0 0 0" rpy="0 1.5708 1.5708" />
        <geometry>
          <cylinder length="0.1" radius="0.2"/>
        </geometry>
        <material name="white"/>
      </visual>

      <inertial>
        <origin xyz="0 0 0" rpy="0 1.5708 1.5708" />
        <mass value="0.2"/>
        <inertia ixx="0.15" ixy="0" ixz="0" iyy="0.15" iyz="0" izz="0.125"/>
      </inertial>

    </link>

    <joint name="base_left_wheel_rear_joint" type="continuous">
      <parent link="base_link"/>
      <child link="left_wheel_rear"/>
      <origin xyz="-0.7 -0.52 -0.31" rpy="0 0 0" />
      <axis xyz="0 1 0" rpy="0 0 0" />
      <limit effort="0" velocity="0"/>
      <dynamics damping="0.0" friction="0.0"/>
    </joint>
  
    <link name="right_wheel_front">
      <collision>
        <origin xyz="0 0 0" rpy="0 1.5708 1.5708" />
        <geometry>
          <cylinder length="0.1" radius="0.2"/>
        </geometry>
      </collision>

      <visual>
        <origin xyz="0 0 0" rpy="0 1.5708 1.5708" />
        <geometry>
          <cylinder length="0.1" radius="0.2"/>
        </geometry>
        <material name="white"/>
      </visual>

      <inertial>
        <origin xyz="0 0 0" rpy="0 1.5708 1.5708" />
        <mass value="0.2"/>
        <inertia ixx="0.15" ixy="0" ixz="0" iyy="0.15" iyz="0" izz="0.125"/>
      </inertial>
    </link>

    <link name="left_wheel_front">
      <collision>
        <origin xyz="0 0 0" rpy="0 1.5708 1.5708" />
        <geometry>
          <cylinder length="0.1" radius="0.2"/>
        </geometry>
      </collision>

      <visual>
        <origin xyz="0 0 0" rpy="0 1.5708 1.5708" />
        <geometry>
          <cylinder length="0.1" radius="0.2"/>
        </geometry>
        <material name="white"/>
      </visual>

      <inertial>
        <origin xyz="0 0 0" rpy="0 1.5708 1.5708" />
        <mass value="0.2"/>
        <inertia ixx="0.15" ixy="0" ixz="0" iyy="0.15" iyz="0" izz="0.125"/>
      </inertial>
    </link>

    <link name="lidar_link">
      <collision>
        <origin xyz="0 0 0" rpy="0 0 0"/>
        <geometry>
          <cylinder radius="0.13" length="0.1"/>
        </geometry>
      </collision>

      <visual>
        <origin xyz="0 0 0" rpy="0 0 0"/>
        <geometry>
          <cylinder radius="0.13" length="0.1"/>
        </geometry>
        <material name="white"/>
      </visual>

      <inertial>
        <origin xyz="0 0 0" rpy="0 0 0"/>
        <mass value="0.1"/>
        <inertia ixx="0.0001" ixy="0" ixz="0" iyy="0.0001" iyz="0" izz="0.0001"/>
      </inertial>

        <sensor name="lidar" type="gpu_ray">
          <pose>0 0 0 0 0 0</pose>
          <update_rate>30</update_rate>
          <ray>
            <scan>
              <horizontal>
                <samples>640</samples>
                <resolution>1</resolution>
                <min_angle>-1.5708</min_angle>
                <max_angle>1.5708</max_angle>
              </horizontal>
              <vertical>
                <samples>1</samples>
                <resolution>1</resolution>
                <min_angle>0</min_angle>
                <max_angle>0</max_angle>
              </vertical>
            </scan>
            <range>
              <min>0.1</min>
              <max>30.0</max>
              <resolution>0.01</resolution>
            </range>
            <noise>
              <type>gaussian</type>
              <mean>0.0</mean>
              <stddev>0.01</stddev>
            </noise>
          </ray>
          <plugin name="ignition::sensors::RaySensor" filename="ignition-sensors-ray-sensor">
            <topic>/scan</topic>
          </plugin>
        </sensor>
    </link>

    <joint name="base_lidar_joint" type="fixed">
      <parent link="base_link"/>
      <child link="lidar_link"/>
      <origin xyz="0 0 0.4" rpy="0 0 0"/>
    </joint>

    <link name="front_left_wheel_steering_link">
      <collision>
        <origin xyz="0 0 0" rpy="0 0 0"/>
        <geometry>
          <cylinder radius="0.04" length="0.2"/>
        </geometry>
      </collision>

      <visual>
        <origin xyz="0 0 0" rpy="0 0 0"/>
        <geometry>
          <cylinder radius="0.04" length="0.2"/>
        </geometry>
        <material name="white"/>
      </visual>

      <inertial>
        <origin xyz="0 0 0" rpy="0 0 0"/>
        <mass value="0.5"/>
        <inertia ixx="0.0153" ixy="0" ixz="0" iyy="0.025" iyz="0" izz="0.0153"/>
      </inertial>
    </link>

    <link name="front_right_wheel_steering_link">
      <collision>
        <origin xyz="0 0 0" rpy="0 0 0"/>
        <geometry>
          <cylinder radius="0.04" length="0.2"/>
        </geometry>
      </collision>

      <visual>
        <origin xyz="0 0 0" rpy="0 0 0"/>
        <geometry>
          <cylinder radius="0.04" length="0.2"/>
        </geometry>
        <material name="white"/>
      </visual>

      <inertial>
        <origin xyz="0 0 0" rpy="0 0 0"/>
        <mass value="0.5"/>
        <inertia ixx="0.0153" ixy="0" ixz="0" iyy="0.025" iyz="0" izz="0.0153"/>
      </inertial>
    </link>

    <joint name="front_left_wheel_steering_joint" type="revolute">
      <parent link="base_link"/>
      <child link="front_left_wheel_steering_link"/>
      <origin xyz="0.7 -0.52 -0.31" rpy="0 0 0"/>
      <axis xyz="0 0 1" rpy="0 0 0"/>
      <limit lower="-0.6" upper="0.6" velocity="1.0" effort="25"/>
    </joint>

    <joint name="front_right_wheel_steering_joint" type="revolute">
      <parent link="base_link"/>
      <child link="front_right_wheel_steering_link"/>
      <origin xyz="0.7 0.52 -0.31" rpy="0 0 0"/>
      <axis xyz="0 0 1" rpy="0 0 0"/>
      <limit lower="-0.6" upper="0.6" velocity="1.0" effort="25"/>
    </joint>

    <joint name="front_left_wheel_joint" type="continuous">
      <parent link="front_left_wheel_steering_link"/>
      <child link="left_wheel_front"/>
      <origin xyz="0 0 0" rpy="0 0 0"/>
      <axis xyz="0 1 0" rpy="0 0 0"/>
      <limit effort="0" velocity="0"/>
      <dynamics damping="0.0" friction="0.0"/>
    </joint>

    <joint name="front_right_wheel_joint" type="continuous">
      <parent link="front_right_wheel_steering_link"/>
      <child link="right_wheel_front"/>
      <origin xyz="0 0 0" rpy="0 0 0"/>
      <axis xyz="0 1 0" rpy="0 0 0"/>
      <limit effort="0" velocity="0"/>
      <dynamics damping="0.0" friction="0.0"/>
    </joint>

    <plugin
      filename="ignition-gazebo-ackermann-steering-system"
      name="gz::sim::systems::AckermannSteering">
      <left_joint>front_left_wheel_joint</left_joint>
      <left_joint>rear_left_wheel_joint</left_joint>
      <right_joint>front_right_wheel_joint</right_joint>
      <right_joint>rear_right_wheel_joint</right_joint>
      <left_steering_joint>front_left_wheel_steering_joint</left_steering_joint>
      <right_steering_joint>front_right_wheel_steering_joint</right_steering_joint>
      <kingpin_width>1.0</kingpin_width>
      <steering_limit>0.5</steering_limit>
      <wheel_base>1.0</wheel_base>
      <wheel_separation>1.25</wheel_separation>
      <wheel_radius>0.3</wheel_radius>
      <min_velocity>-1</min_velocity>
      <max_velocity>1</max_velocity>
      <min_acceleration>-3</min_acceleration>
      <max_acceleration>3</max_acceleration>
      <odom_publish_frequency>1</odom_publish_frequency>
      <topic>/model/my_robot/cmd_vel</topic>
    </plugin>

</robot>